Workbook

Sheet 汇总表
A1: MIDEA | B1: MDV | C1: CODE | D1: PRICE
A2: MV6-252WV2GN1 | B2: MDV6-252WV2GN1 | C2: 22027020001129 | D2: 2531
A3: MV6-280WV2GN1 | B3: MDV6-280WV2GN1 | C3: 22027020001127 | D3: 2609
A4: MV6-335WV2GN1 | B4: MDV6-335WV2GN1 | C4: 22027020001128 | D4: 2898
A5: MV6-400WV2GN1 | B5: MDV6-400WV2GN1 | C5: 22027020001186 | D5: 3389
A6: MV6-450WV2GN1 | B6: MDV6-450WV2GN1 | C6: 22027020001185 | D6: 3537
A7: MV6-500WV2GN1 | B7: MDV6-500WV2GN1 | C7: 22027020001145 | D7: 4238
A8: MV6-560WV2GN1 | B8: MDV6-560WV2GN1 | C8: 22027020001146 | D8: 4349
A9: MV6-615WV2GN1 | B9: MDV6-615WV2GN1 | C9: 22027020001147 | D9: 4641
A10: MV6-670WV2GN1 | B10: MDV6-670WV2GN1 | C10: 22027020001148 | D10: 5220
A11: MV6-730WV2GN1 | B11: MDV6-730WV2GN1 | C11: 22027020001149 | D11: 5463
A12: MV6-785WV2GN1 | B12: MDV6-785WV2GN1 | C12: 22027020001150 | D12: 5717
A13: MV6-850WV2GN1 | B13: MDV6-850WV2GN1 | C13: 22027020001125 | D13: 6166
... A27: MV6-i900WV2GN1 | B27: MDV6-i900WV2GN1 | C27: 22027020001006 | D27: 5672
A28: MV6-R252WV2GN1 | C28: 22027020001825 | D28: 2850
A29: MV6-R280WV2GN1 | C29: 22027020001865 | D29: 2950
A30: MV6-R335WV2GN1 | C30: 22027020001866 | D30: 3350
A31: MV6-R400WV2GN1 | C31: 22027020001885 | D31: 3850
A32: MV6-R450WV2GN1 | C32: 22027020001886 | D32: 4050
A33: MV6-R500WV2GN1 | C33: 22027020001845 | D33: 4250
A34: MV6-R560WV2GN1 | C34: 22027020001965 | D34: 4550
A35: MV5-X252W/V2GN1 | B35: MDV5-X252W/V2GN1 | C35: 22027020000119 | D35: 2412
A36: MV5-X280W/V2GN1 | B36: MDV5-X280W/V2GN1 | C36: 22027020000064 | D36: 2558
A37: MV5-X335W/V2GN1 | B37: MDV5-X335W/V2GN1 | C37: 22027020000214 | D37: 2896
A38: MV5-X400W/V2GN1 | B38: MDV5-X400W/V2GN1 | C38: 22027020000058 | D38: 3280
A39: MV5-X450W/V2GN1 | B39: MDV5-X450W/V2GN1 | C39: 22027020000025 | D39: 3520
A40: MV5-X500W/V2GN1 | B40: MDV5-X500W/V2GN1 | C40: 22027020000055 | D40: 3907
A41: MV5-X560W/V2GN1 | B41: MDV5-X560W/V2GN1 | C41: 22027020000127 | D41: 4318
A42: MV5-X615W/V2GN1 | B42: MDV5-X615W/V2GN1 | C42: 22027020000037 | D42: 4623
A43: MDVS-252(8)W/DRN1 | B43: MDVS-252(8)W/DRN1 | C43: 22027020000241 | D43: 2062
A44: MDVS-280(10)W/DRN1 | B44: MDVS-280(10)W/DRN1 | C44: 22027020000228 | D44: 2196
A45: MDVS-335(12)W/DRN1 | B45: MDVS-335(12)W/DRN1 | C45: 22027020000067 | D45: 2358
A46: MDV-V200W/DRN1 | B46: MDV-V200W/DRN1 | C46: 22027020000260 | D46: 1523
... A96: MI2-45Q4CDHN1 | B96: MDI2-45Q4CDHN1 | C96: 22026012000601 | D96: 237
D97: 30
A98: MI2-28Q4DHN1 | B98: MDI2-28Q4DHN1 | C98: 22026012000691 | D98: 184
A99: MI2-36Q4DHN1 | B99: MDI2-36Q4DHN1 | C99: 22026012000689 | D99: 193
A100: MI2-45Q4DHN1 | B100: MDI2-45Q4DHN1 | C100: 22026012000690 | D100: 229
A101: MI2-56Q4DHN1 | B101: MDI2-56Q4DHN1 | C101: 22026012000688 | D101: 235
A102: MI2-71Q4DHN1 | B102: MDI2-71Q4DHN1 | C102: 22026012000687 | D102: 289
...

Sheet V8 
I1: 0.38
A2: Series | B2: Power Supply | C2: Midea Model | D2: Factory code | E2: Description | F2: Capacity Kw | G2: Прайс Лист (розница) | I2: Цена со скидкой 62% | J2: комплект цена
A3: V8 Master | B3: 380-415V ~ 3N ~ 50/60Hz | C3: MV8-252WV2GN1(MA) | D3: 22027020002389 | E3: 1.Chassis electrical heater 2.Automatic refrigerant charging 3.Bluetooth module (with black box) 4.single outdoor unit ratio 200% 5. V8 system can connect 30% indoor units 6. Auto dust-clean function 7. Humidity control (in IDU) | F3: 25.2 | G3: 16697 | I3: 6345
C4: MV8-280WV2GN1(MA) | D4: 22027020002392 | F4: 28 | G4: 17205 | I4: 6538
C5: MV8-335WV2GN1(MA) | D5: 22027020002305 | F5: 33.5 | G5: 19112 | I5: 7263
C6: MV8-400WV2GN1(MA) | D6: 22027020002397 | F6: 40 | G6: 22349 | I6: 8493
C7: MV8-450WV2GN1(MA) | D7: 22027020002391 | F7: 45 | G7: 23326 | I7: 8864
C8: MV8-500WV2GN1(MA) | D8: 22027020002265 | F8: 50 | G8: 27951 | I8: 10622
C9: MV8-560WV2GN1(MA) | D9: 22027020002347 | F9: 56 | G9: 28670 | I9: 10895
C10: MV8-615WV2GN1(MA) | D10: 22027020002346 | F10: 61.5 | G10: 30606 | I10: 11631
C11: MV8-670WV2GN1(MA) | D11: 22027020002345 | F11: 67 | G11: 34426 | I11: 13082
C12: MV8-730WV2GN1(MA) | D12: 22027020002365 | F12: 73 | G12: 36025 | I12: 13690
C13: MV8-785WV2GN1(MA) | D13: 22027020002286 | F13: 78.5 | G13: 37698 | I13: 14326
C14: MV8-850WV2GN1(MA) | D14: 22027020002285 | F14: 85 | G14: 40661 | I14: 15452
C15: MV8-900WV2GN1(MA) | D15: 22027020002393 | F15: 90 | G15: 40981 | I15: 15573
... C19: MV8-1120WV2GN1(MA) | D19: 22027020002325 | F19: 112 | G19: 47325 | I19: 17984
A20: V8i Master | B20: 380-415V ~ 3N ~ 50/60Hz | C20: MV8i-252WV2GN1(MA) | D20: 22027020002647 | E20: 1.Chassis electrical heater 2.Automatic refrigerant charging 3.Bluetooth module (with black box) 4.single outdoor unit ratio 200% 5. V8 system can connect 30% indoor units 6. Auto dust-clean function 7. Humidity control (in IDU) | F20: 25.2 | G20: 13739 | I20: 5221
C21: MV8i-280WV2GN1(MA) | D21: 22027020002633 | F21: 28 | G21: 13996 | I21: 5319
C22: MV8i-335WV2GN1(MA) | D22: 22027020002646 | F22: 33.5 | G22: 16074 | I22: 6109
C23: MV8i-400WV2GN1(MA) | D23: 22027020002637 | F23: 40 | G23: 18798 | I23: 7144
C24: MV8i-450WV2GN1(MA) | D24: 22027020002623 | F24: 45 | G24: 19095 | I24: 7257
C25: MV8i-500WV2GN1(MA) | D25: 22027020002645 | F25: 50 | G25: 21270 | I25: 8083
C26: MV8i-560WV2GN1(MA) | D26: 22027020002629 | F26: 56 | G26: 22538 | I26: 8565
C27: MV8i-615WV2GN1(MA) | D27: 22027020002630 | F27: 61.5 | G27: 24565 | I27: 9335
C28: MV8i-670WV2GN1(MA) | D28: 22027020002627 | F28: 67 | G28: 26906 | I28: 10225
C29: MV8i-730WV2GN1(MA) | D29: 22027020002608 | F29: 73 | G29: 33781 | I29: 12837
C30: MV8i-785WV2GN1(MA) | D30: 22027020002609 | F30: 78.5 | G30: 34055 | I30: 12941
C31: MV8i-850WV2GN1(MA) | D31: 22027020002619 | F31: 85 | G31: 35163 | I31: 13362
C32: MV8i-900WV2GN1(MA) | D32: 22027020002618 | F32: 90 | G32: 37407 | I32: 14215
... C37: MV8i-1170WV2GN1(MA) | D37: 22027020002614 | F37: 117 | G37: 43105 | I37: 16380
A38: VC MAX | B38: 380-415V ~ 3N ~ 50/60Hz | C38: MVC-M224WV2GN1 | D38: 22027020003247 | E38: 1.Automatic refrigerant charging 2.Bluetooth module (with black box) 3.single outdoor unit ratio 200% 4. V8 system can connect 30% indoor units 5. Auto dust-clean function 6. Humidity control (in IDU) | F38: 22.4 | G38: 7823 | I38: 2973
C39: MVC-M280WV2GN1 | D39: 22027020003245 | F39: 28 | G39: 8394 | I39: 3190
C40: MVC-M335WV2GN1 | D40: 22027020003225 | F40: 33.5 | G40: 8674 | I40: 3297
C41: MVC-M400WV2GN1 | D41: 22027020003246 | F41: 40 | G41: 11398 | I41: 4332
C42: MVC-M450WV2GN1 | D42: 22027020003165 | F42: 45 | G42: 11438 | I42: 4347
C43: MVC-M500WV2GN1 | D43: 22027020003188 | F43: 50 | G43: 15058 | I43: 5723
C44: MVC-M560WV2GN1 | D44: 22027020003205 | F44: 56 | G44: 15086 | I44: 5733
C45: MVC-M615WV2GN1 | D45: 22027020003189 | F45: 61.5 | G45: 16731 | I45: 6358
C46: MVC-M670WV2GN1 | D46: 22027020003190 | F46: 67 | G46: 18267 | I46: 6942
C47: MVC-M730WV2GN1 | D47: 22027020003185 | F47: 73 | G47: 18472 | I47: 7020
...

Sheet VRF
A1: Series | B1: Midea model | C1: Code | D1: Description of Goods | E1: Capacity (Kw) | F1: Прайс Лист (розница) | H1: Цена со скидкой 62%
A2: V6R Series Series with automatic refrigerant charging function | B2: MV6-R252WV2GN1 | C2: 22027020001825 | D2: 380~415V-3PH 50(60)Hz Series with automatic refrigerant charging function Output limitation control; Full DC inverter EVI compressor; Night silent modes+ silent modes +super silent modes; EMS (Energy Management System); Wrong connection protection; Alarm output; Maximum ESP 80 Pa; Black Box; Mr. Doctor; Auto dust-clean function; Hot water supply; | E2: 25.2 | F2: 18161 | H2: 6902
B3: MV6-R280WV2GN1 | C3: 22027020001865 | E3: 28 | F3: 18788 | H3: 7140
B4: MV6-R335WV2GN1 | C4: 22027020001866 | E4: 33.5 | F4: 21318 | H4: 8101
B5: MV6-R400WV2GN1 | C5: 22027020001885 | E5: 40 | F5: 24488 | H5: 9306
B6: MV6-R450WV2GN1 | C6: 22027020001886 | E6: 45 | F6: 25759 | H6: 9789
B7: MV6-R500WV2GN1 | C7: 22027020001845 | E7: 50 | F7: 27018 | H7: 10267
B8: MV6-R560WV2GN1 | C8: 22027020001965 | E8: 56 | F8: 28917 | H8: 10989
A9: V6-i侧出风外机 VRF V6-i ODU | B9: MVi-200WV2GN1(A) | C9: 22027020002045 | D9: VRF outdoor 380~415V-3PH 50(60)Hz All DC invertor Side discharge | E9: 20 | F9: 8100 | H9: 3078
B10: MVi-224WV2GN1(A) | C10: 22027020002046 | E10: 22.4 | F10: 8357 | H10: 3176
B11: MVi-260WV2GN1(A) | C11: 22027020002047 | E11: 26 | F11: 8642 | H11: 3284
B12: MVi-280WV2GN1(A) | C12: 22027020002048 | E12: 28 | F12: 8995 | H12: 3419
B13: MVi-335WV2GN1(A) | C13: 22027020002049 | E13: 33.5 | F13: 10449 | H13: 3971
A14: VC-i - side discharge | B14: MDVC-V200W/DRN1 | C14: 22027020001945 | E14: 20 | F14: 6476 | H14: 2461
B15: MDVC-V224W/DRN1 | C15: 22027020001946 | E15: 22.4 | F15: 6658 | H15: 2531
B16: MDVC-V260W/DRN1 | C16: 22027020001947 | E16: 26 | F16: 6732 | H16: 2559
B17: MDVC-V280W/DRN1 | C17: 22027020001925 | E17: 28 | F17: 6778 | H17: 2576
A18: Water source V4+ W series | B18: MDVS-252(8)W/DRN1 | C18: 22027020000241 | D18: Water source DC inverter, R410A, 380V, outdoor unit Modular type | E18: 25.2 | F18: 13048 | H18: 4959
B19: MDVS-280(10)W/DRN1 | C19: 22027020000228 | E19: 28 | F19: 13897 | H19: 5281
B20: MDVS-335(12)W/DRN1 | C20: 22027020000067 | E20: 33.5 | F20: 14929 | H20: 5674
A21: 3-Pipe VRF model switch box | B21: MS01N1-D | C21: 22010200000195 | D21: model switch box, one drive 1 | E21: / | F21: 2303 | H21: 876
B22: MS04N1-D | C22: 22010200000219 | D22: model switch box, one drive 4 | E22: / | F22: 4549 | H22: 1729
B23: MS06N1-D | C23: 22010200000218 | D23: model switch box, one drive 6 | E23: / | F23: 6151 | H23: 2338
B24: MS08N1-D | C24: 22010200000217 | D24: model switch box, one drive 8 | E24: / | F24: 7713 | H24: 2931
B25: MS10N1-D | C25: 22010200000216 | D25: model switch box, one drive 10 | E25: / | F25: 9166 | H25: 3484
B26: MS12N1-D | C26: 22010200000215 | D26: model switch box, one drive 12 | E26: / | F26: 10557 | H26: 4012
A27: Mini C 2rd geneartion | B27: MDV-V80W/DHN1(D) | C27: 22027020002077 | D27: All DC inverter; single phase; R410A; 220V | F27: 3306 | H27: 1257
B28: MDV-V100W/DHN1(D) | C28: 22027020002078 | F28: 4281 | H28: 1627
B29: MDV-V120W/DHN1(D) | C29: 22027020002079 | F29: 5142 | H29: 1954
B30: MDV-V140W/DHN1(D) | C30: 22027020002080 | F30: 5609 | H30: 2132
B31: MDV-V160W/DHN1(D) | C31: 22027020002081 | F31: 6316 | H31: 2401
B32: MDV-V180W/DHN1(D) | C32: 22027020002105 | F32: 6424 | H32: 2442
A33: AC HRV | B33: HRV-200 | C33: 22026022000019 | D33: 220-240V ~ 50Hz | E33: 200m3/h | F33: 1437 | H33: 547
B34: HRV-300 | C34: 22026022000018 | E34: 300m3/h | F34: 1733 | H34: 659
B35: HRV-400 | C35: 22026022000011 | E35: 400m3/h | F35: 2087 | H35: 794
B36: HRV-500 | C36: 22026022000016 | E36: 500m3/h | F36: 2879 | H36: 1095
B37: HRV-800 | C37: 22026022000009 | E37: 800m3/h | F37: 3740 | H37: 1422
B38: HRV-1000 | C38: 22026022000012 | E38: 1000m3/h | F38: 4367 | H38: 1660
B39: HRV-1500 | C39: 22026022000001 | D39: 380-415V ~ 3N ~ 50Hz | E39: 1500m3/h | F39: 6362 | H39: 2418
B40: HRV-2000 | C40: 22026022000017 | E40: 2000m3/h | F40: 7445 | H40: 2830
...

Sheet Atom
H1: 0.38
A2: Series | B2: MIDEA MODEL | C2: Code | D2: Description of Goods | E2: Capacity | F2: Прайс Лист (розница) | H2: Цена со скидкой 62% | I2: комплект цена
A3: ATOM OU Cooling and Heating (Примечание : в прайсе с продажными ценами старшая модель "V68" ошибочно называется "V72" | B3: MDV-V12WDHN1(AtB) | C3: 22027020002147 | D3: Heat pump, inverter type ODU | E3: 3.5 | F3: 2229 | H3: 848
B4: MDV-V18WDHN1(AtB) | C4: 22027020002146 | E4: 5.3 | F4: 2400 | H4: 912
B5: MDV-V21WDHN1(AtB) | C5: 22027020002145 | E5: 6.2 | F5: 2571 | H5: 977
B6: MDV-V28WDHN1(AtB) | C6: 22027020002077 | E6: 8 | F6: 2994 | H6: 1138
B7: MDV-V36WDHN1A(AtB) | C7: 22027020003485 | E7: 10.5 | F7: 3537 | H7: 1345
B8: MDV-V42WDHN1A(AtB) | C8: 22027020003425 | E8: 12 | F8: 4067 | H8: 1546
B9: MDV-V48WDHN1(AtB) | C9: 22027020002080 | E9: 14 | F9: 4357 | H9: 1656
B10: MDV-V56WDHN1(AtB) | C10: 22027020002081 | E10: 16 | F10: 4908 | H10: 1866
B11: MDV-V60WDHN1(AtB) | C11: 22027020002105 | E11: 18 | F11: 5984 | H11: 2274
B12: MDV-V68WDHN1(AtB) | C12: CBO 22027020003365 | E12: 20 | F12: 6246 | H12: 2374
A13: ATOM Branch pipe assembly | B13: DXFQT2-02 | C13: 15111700001940 | D13: Branch pipe assembly, mini VRF only | E13: / | F13: 160 | H13: 61
B14: DXFQT3-02 | C14: 15111700001936 | D14: Branch pipe assembly, mini VRF only | E14: / | F14: 223 | H14: 85
B15: DXFQT4-02 | C15: 15111700001942 | D15: Branch pipe assembly, mini VRF only | E15: / | F15: 280 | H15: 107
B16: DXFQT5-02 | C16: 15111700001934 | D16: Branch pipe assembly, mini VRF only | E16: / | F16: 320 | H16: 122
B17: DXFQT6-02 | C17: 15111700001938 | D17: Branch pipe assembly, mini VRF only | E17: / | F17: 377 | H17: 144
B18: RM12F | C18: 17317000008018 | E18: / | F18: 63 | H18: 24
B19: WDC-86E/K | C19: 17317100003095 | E19: / | F19: 109 | H19: 42
A20: ATOM CCU connection kit | B20: VCCUKZ-00(at) | C20: 22012000000134 | D20: 2,2 - 9,0kW | E20: / | F20: 759 | H20: 289
B21: VCCUKZ-01(at) | C21: 22012000000133 | D21: 9,0 - 16,0 kW | E21: / | F21: 764 | H21: 291
A22: Atom T ODU(EU Series) | B22: MDV-V80WHN8(At) | C22: 22027020003085 | E22: 8 | F22: 2862 | H22: 1088
B23: MDV-V100WHN8(At) | C23: 22027020003086 | E23: 10 | F23: 3643 | H23: 1385
B24: MDV-V120WHN8(At) | C24: 22027020003006 | E24: 12 | F24: 4378 | H24: 1664
B25: MDV-V140WHN8(At) | C25: 22027020003005 | E25: 14 | F25: 4783 | H25: 1818
B26: MDV-V160WHN8(At) | C26: 22027020003007 | E26: 16 | F26: 5381 | H26: 2045
A27: Atom T IDU with water tank | B27: SMKT-D100/190CGN8(At) | C27: 22025314000831 | E27: 190L | F27: 10642 | H27: 4044
B28: SMKT-D160/240CGN8(At) | C28: 22025314000832 | E28: 240L | F28: 12438 | H28: 4727
A29: hydraulic module | B29: SMK-D160N8(At) | C29: 22025314000811 | E29: 16 | F29: 5871 | H29: 2231
A30: DHW Kit | B30: MHWK-120HN8 | C30: 22012000000191 | E30: 12.3 | F30: 816 | H30: 311
A31: DHW Tank | B31: MT-200R26E20 | C31: 22025331000101 | E31: / | F31: 2235 | H31: 850
B32: MT-300R26E20 | C32: 22025331000081 | E32: / | F32: 2719 | H32: 1034
A33: AtomC VRF Cooling only | B33: MDVC-V28WDHN1(AtC) | C33: 22027020003467 | D33: Cooling only Mini VRF, 220-240V ~ 50/60Hz Customization number (EXV) - PZ2024102834128 | E33: 8 | F33: 2337 | H33: 889
B34: MDVC-V36WDHN1(AtC) | C34: 22027020003465 | E34: 10 | F34: 3033 | H34: 1153
B35: MDVC-V42WDHN1(AtC) | C35: 22027020003466 | E35: 12 | F35: 3648 | H35: 1387
B36: MDVC-V48WDHN1(AtC) | C36: 22027020003446 | E36: 14 | F36: 3985 | H36: 1515
B37: MDVC-V56WDHN1(AtC) | C37: 22027020003447 | E37: 16 | F37: 4486 | H37: 1705
B38: MDVC-V60WDHN1(AtC) | C38: 22027020003445 | E38: 18 | F38: 5370 | H38: 2041
A39: ATOM V8 IDU Wall-mounted | B39: MI2-05GDHN18(At) | C39: 22026010000581 | D39: Long-distance on/off function Long-distance alarm function X1X2, PQE, D1D2 Indoor temperature detection control Including remote controller RM12F1 Panel Z-HS-C1 | E39: 1.5 | F39: 496 | H39: 189
B40: MI2-07GDHN18(At) | C40: 22026010000583 | E40: 2.2 | F40: 519 | H40: 198
...

Sheet Unitary
A1: Series | B1: Type | D1: MIDEA model | E1: Code | F1: Description of Goods | G1: Capacity (kw) | H1: Прайс Лист (розница) | I1: Цена со скидкой 62%
A2: Industrial floor standing indoor units | B2: Cooling&heating | C2: Side discharge | D2: MFSL-76HDN1 | E2: 22026014000375 | G2: 22 | H2: 3417 | I2: 1299
D3: MFSL-96HDN1 | E3: 22026014000385 | G3: 28 | H3: 3518 | I3: 1337
D4: MFSL-120HDN1 | E4: 22026014000367 | G4: 35 | H4: 3729 | I4: 1418
D5: MFSL-150HDN1 | E5: 22026014000370 | G5: 45 | H5: 4031 | I5: 1532
D6: MFSL-192HDN1 | E6: 22026014000382 | G6: 56 | H6: 5025 | I6: 1910
C7: Top discharge | D7: MFTL-76HDN1 | E7: 22026014000365 | G7: 22 | H7: 3347 | I7: 1272
D8: MFTL-96HDN1 | E8: 22026014000369 | G8: 28 | H8: 3528 | I8: 1341
D9: MFTL-120HDN1 | E9: 22026014000376 | G9: 35 | H9: 3654 | I9: 1389
D10: MFTL-150HDN1 | E10: 22026014000366 | G10: 45 | H10: 4593 | I10: 1746
D11: MFTL-192HDN1 | E11: 22026014000380 | G11: 56 | H11: 4915 | I11: 1868
A12: Quantum duct indoor units | C12: High static pressure duct | D12: MHG-28HAN1 | E12: 借22026011001641 | G12: 8 | H12: 1850 | I12: 703
D13: MHG-48HAN1 | E13: 借22026011001665 | G13: 14 | H13: 2382 | I13: 906
D14: MHG-68HAN1 | E14: 借22026011001698 | G14: 20 | H14: 4081 | I14: 1551
D15: MHG-76HAN1 | E15: 借22026011001699 | G15: 22 | H15: 4292 | I15: 1631
D16: MHG-96HAN1 | E16: 借22026011001707 | G16: 28 | H16: 4603 | I16: 1750
D17: MHG-120HAN1 | E17: 借22026011001679 | G17: 35 | H17: 5091 | I17: 1935
D18: MHG-140HAN1 | E18: 借22026011001706 | G18: 40 | H18: 6649 | I18: 2527
D19: MHG-150HAN1 | E19: 借22026011001705 | G19: 45 | H19: 6819 | I19: 2592
D20: MHG-192HAN1 | E20: 借22026011001681 | G20: 56 | H20: 7131 | I20: 2710
A21: Universal outdoor units | C21: Universal outdoor units | D21: MOUG-28HD1N1-R | E21: 借22027020002077 | G21: 8 | H21: 1995 | I21: 759
D22: MOUG-48HD1N1-R | E22: 借22027020002080 | G22: 14 | H22: 3106 | I22: 1181
D23: MOUG-68HD1N1-R | E23: 借22027020002050 | G23: 20 | H23: 6262 | I23: 2380
D24: MOUG-76HD1N1-R | E24: 借22027020002051 | G24: 22 | H24: 6503 | I24: 2472
D25: MOUG-96HD1N1-R | E25: 借22027020002053 | G25: 28 | H25: 8458 | I25: 3215
D26: MOUG-120HD1N1-R | E26: 借22027020002054 | G26: 35 | H26: 10010 | I26: 3804
D27: MOUG-140HD1N1-R | E27: 借22027020002569 | G27: 40 | H27: 11372 | I27: 4322
D28: MOUG-150HD1N1-R | E28: 借22027020002574 | G28: 45 | H28: 13965 | I28: 5307
D29: MOUG-192HD1N1-R | E29: 借22027020002570 | G29: 56 | H29: 16136 | I29: 6132
A30: Quantum duct indoor units CB certificate R410A | B30: Cooling&heating | C30: High static pressure duct | D30: MHL-68HDN1 | E30: 借22026011001838 | F30: 1.220-240V,1Ph,50/60Hz 2.standard with WDC3-86S controller | G30: 19.928828 | H30: 2739 | I30: 1041
D31: MHL-76HDN1 | E31: 借22026011001839 | G31: 22.273396 | H31: 2890 | I31: 1099
D32: MHL-96HDN1 | E32: 借22026011001840 | G32: 28.134816 | H32: 2930 | I32: 1114
D33: MHL-120HDN1 | E33: 借22026011001678 | G33: 35.16852 | H33: 3694 | I33: 1404
D34: MHL-150HDN1 | E34: 借22026011001703 | G34: 43.96065 | H34: 4855 | I34: 1845
D35: MHL-192HDN1 | E35: 借22026011001680 | G35: 56.269632 | H35: 5156 | I35: 1960
C36: Middle static pressure duct | D36: MTL-24HDN1 | E36: 借22026011001518 | G36: 7.033704 | H36: 1031 | I36: 392
D37: MTL-36HDN1 | E37: 借22026011001500 | G37: 10.550556 | H37: 1317 | I37: 501
D38: MTL-40HDN1 | E38: 借22026011001500 | G38: 11.72284 | H38: 1342 | I38: 510
D39: MTL-48HDN1 | E39: 借22026011001511 | G39: 14.067408 | H39: 1438 | I39: 547
A40: Universal outdoor units CB certificate R410A | B40: Cooling&heating | C40: Universal outdoor units | D40: MOUL-68HD1N1-G | E40: 借22027020002045 | F40: 380-415V 3N~50/60Hz | G40: 19.928828 | H40: 5870 | I40: 2231
...

Sheet FCU-Duct
H1: 0.38
A2: series | B2: type | C2: Midea model | D2: Capacity (CFM) | E2: BOM code | F2: Description of Goods | G2: Прайс Лист (розница) | H2: Цена со скидкой 62%
A3: Duct | B3: MK-CBS Duct of 3-Row (right connection) | C3: MKT3-200G12-CR | D3: 200 | E3: CBO 22026211000561 | F3: 1. 3-row coil, 12 pa; 2. Standard with air return plenum and fitler, air intake from rear 3. Two pipe fancoil | G3: 442 | H3: 168 | I3: =H3+$H$91 -> 225
C4: MKT3-300G12-CR | D4: 300 | E4: CBO 22026211000540 | G4: 481 | H4: 183 | I4: =H4+$H$91 -> 240
C5: MKT3-400G12-CR | D5: 400 | E5: CBO 22026211000564 | G5: 533 | H5: 203 | I5: =H5+$H$91 -> 260
C6: MKT3-500G12-CR | D6: 500 | E6: CBO 22026211000580 | G6: 579 | H6: 221 | I6: =H6+$H$91 -> 278
C7: MKT3-600G12-CR | D7: 600 | E7: CBO 22026211000560 | G7: 624 | H7: 238 | I7: =H7+$H$91 -> 295
C8: MKT3-700G12-CR | D8: 700 | E8: CBO 22026211000562 | G8: 774 | H8: 295 | I8: =H8+$H$91 -> 352
C9: MKT3-800G12-CR | D9: 800 | E9: CBO 22026211000542 | G9: 884 | H9: 336 | I9: =H9+$H$91 -> 393
C10: MKT3-1000G12-CR | D10: 1000 | E10: CBO 22026211000565 | G10: 930 | H10: 354 | I10: =H10+$H$91 -> 411
C11: MKT3-1200G12-CR | D11: 1200 | E11: CBO 22026211000566 | G11: 1008 | H11: 384 | I11: =H11+$H$91 -> 441
C12: MKT3-1400G12-CR | D12: 1400 | E12: CBO 22026211000563 | G12: 1118 | H12: 425 | I12: =H12+$H$91 -> 482
B13: MK-CBS Duct of 3-Row (right connection) | C13: MKT3-200G30-CR | D13: 200 | E13: 22026211000561 | F13: 1. 3-row coil, 30 pa; 2. Standard with air return plenum and fitler, air intake from rear 3. Two pipe fancoil | G13: 429 | H13: 164 | I13: =H13+$H$91 -> 221
C14: MKT3-300G30-CR | D14: 300 | E14: 22026211000540 | G14: 488 | H14: 186 | I14: =H14+$H$91 -> 243
C15: MKT3-400G30-CR | D15: 400 | E15: 22026211000564 | G15: 520 | H15: 198 | I15: =H15+$H$91 -> 255
C16: MKT3-500G30-CR | D16: 500 | E16: 22026211000580 | G16: 559 | H16: 213 | I16: =H16+$H$91 -> 270
C17: MKT3-600G30-CR | D17: 600 | E17: 22026211000560 | G17: 618 | H17: 235 | I17: =H17+$H$91 -> 292
C18: MKT3-700G30-CR | D18: 700 | E18: 22026211000562 | G18: 800 | H18: 304 | I18: =H18+$H$91 -> 361
C19: MKT3-800G30-CR | D19: 800 | E19: 22026211000542 | G19: 871 | H19: 331 | I19: =H19+$H$91 -> 388
C20: MKT3-1000G30-CR | D20: 1000 | E20: 22026211000565 | G20: 923 | H20: 351 | I20: =H20+$H$91 -> 408
C21: MKT3-1200G30-CR | D21: 1200 | E21: 22026211000566 | G21: 1027 | H21: 391 | I21: =H21+$H$91 -> 448
C22: MKT3-1400G30-CR | D22: 1400 | E22: 22026211000563 | G22: 1118 | H22: 425 | I22: =H22+$H$91 -> 482
B23: MK-CBS Duct of 3-Row (right connection) | C23: MKT3-200G50-CR | D23: 200 | E23: CBO 22026211000561 | F23: 1. 3-row coil, 50 pa; 2. Standard with air return plenum and fitler, air intake from rear 3. Two pipe fancoil | G23: 468 | H23: 178 | I23: =H23+$H$91 -> 235
C24: MKT3-300G50-CR | D24: 300 | E24: CBO 22026211000540 | G24: 533 | H24: 203 | I24: =H24+$H$91 -> 260
C25: MKT3-400G50-CR | D25: 400 | E25: CBO 22026211000564 | G25: 559 | H25: 213 | I25: =H25+$H$91 -> 270
C26: MKT3-500G50-CR | D26: 500 | E26: CBO 22026211000580 | G26: 605 | H26: 230 | I26: =H26+$H$91 -> 287
C27: MKT3-600G50-CR | D27: 600 | E27: CBO 22026211000560 | G27: 670 | H27: 255 | I27: =H27+$H$91 -> 312
C28: MKT3-700G50-CR | D28: 700 | E28: CBO 22026211000562 | G28: 832 | H28: 317 | I28: =H28+$H$91 -> 374
C29: MKT3-800G50-CR | D29: 800 | E29: CBO 22026211000542 | G29: 936 | H29: 356 | I29: =H29+$H$91 -> 413
C30: MKT3-1000G50-CR | D30: 1000 | E30: CBO 22026211000565 | G30: 995 | H30: 379 | I30: =H30+$H$91 -> 436
C31: MKT3-1200G50-CR | D31: 1200 | E31: CBO 22026211000566 | G31: 1118 | H31: 425 | I31: =H31+$H$91 -> 482
C32: MKT3-1400G50-CR | D32: 1400 | E32: CBO 22026211000563 | G32: 1203 | H32: 458 | I32: =H32+$H$91 -> 515
A33: HSP duct fancoil | B33: MDKT3H-G70(100) | C33: MKT3H-800G70 | D33: 800 | F33: 1. 3-row coil, 70~100 pa; 2. Brand new desgin; 3. Standard with air return plenum and fitler, air intake from rear 4. Two pipe fancoil; 5. Drain pan for heat exchanger standard; 6. Drain pan for for 3way valve is option | G33: 1105 | H33: 420
C34: MKT3H-1000G70 | D34: 1000 | G34: 1183 | H34: 450
C35: MKT3H-1200G70 | D35: 1200 | G35: 1235 | H35: 470
C36: MKT3H-1400G70 | D36: 1400 | G36: 1320 | H36: 502
C37: MKT3H-1600G100 | D37: 1600 | G37: 1651 | H37: 628
C38: MKT3H-1800G100 | D38: 1800 | G38: 1807 | H38: 687
C39: MKT3H-2200G100 | D39: 2200 | G39: 1937 | H39: 737
B40: MDKT3H-EG70(100) | C40: MKT3H-800EG70 | D40: 800 | F40: 1. 3-row coil, 70~100 pa; 2. Brand new desgin; 3. Standard with air return plenum and fitler, air intake from rear 4. Two pipe fancoil 5.With EAH | G40: 1378 | H40: 524
...

Sheet FCU-other
I1: 0.38
A2: series | B2: MIDEA model | C2: Code | D2: Capacity (CFM) | E2: Description of Goods | F2: Photo | G2: Прайс Лист (розница) | I2: Цена со скидкой 62%
A3: New appearance Ceiling floor | B3: MKH1-150-R3 | C3: 22026214000107 | D3: 150 | E3: 1. two pipe fancoil; 2. air intake from front; 3. casing with grills on intake and outlet side; 4. drain pan for heat exchanger is standard (drain pan for 3 way valve is option) 5. Flexible installation | G3: 709 | I3: 270
B4: MKH1-250-R3 | C4: 22026214000109 | D4: 250 | G4: 761 | I4: 290
B5: MKH1-350-R3 | C5: 22026214000110 | D5: 300 | G5: 884 | I5: 336
B6: MKH1-500-R3 | C6: 22026214000116 | D6: 500 | G6: 988 | I6: 376
B7: MKH1-700-R3 | C7: 22026214000115 | D7: 700 | G7: 1066 | I7: 406
B8: MKH1-800-R3 | C8: 22026214000117 | D8: 800 | G8: 1177 | I8: 448
B9: MKH1-150-R4 | C9: 22026214000108 | D9: 150 | G9: 722 | I9: 275
B10: MKH1-250-R4 | C10: 22026214000111 | D10: 250 | G10: 800 | I10: 304
B11: MKH1-350-R4 | C11: 22026214000112 | D11: 300 | G11: 923 | I11: 351
B12: MKH1-500-R4 | C12: 22026214000114 | D12: 500 | G12: 1008 | I12: 384
B13: MKH1-700-R4 | C13: 22026214000113 | D13: 700 | G13: 1131 | I13: 430
B14: MKH1-800-R4 | C14: 22026214000118 | D14: 800 | G14: 1242 | I14: 472
A15: New appearance Ceiling floor | B15: MKH2-150-R3 | C15: 22026214000107 | D15: 150 | E15: 1. two pipe fancoil; 2. air intake from rear; 3. casing with grills on intake and outlet side; 4. drain pan for heat exchanger is standard (drain pan for 3 way valve is option) 5. Flexible installation | G15: 709 | I15: 270
B16: MKH2-250-R3 | C16: 22026214000109 | D16: 250 | G16: 761 | I16: 290
B17: MKH2-350-R3 | C17: 22026214000110 | D17: 350 | G17: 884 | I17: 336
B18: MKH2-500-R3 | C18: 22026214000116 | D18: 500 | G18: 988 | I18: 376
B19: MKH2-700-R3 | C19: 22026214000115 | D19: 700 | G19: 1066 | I19: 406
B20: MKH2-800-R3 | C20: 22026214000117 | D20: 800 | G20: 1177 | I20: 448
B21: MKH2-150-R4 | C21: 22026214000108 | D21: 150 | G21: 722 | I21: 275 | J21: =I21+$I$40+53 -> 346
B22: MKH2-250-R4 | C22: 22026214000111 | D22: 250 | G22: 800 | I22: 304 | J22: =I22+$I$40+53 -> 375
B23: MKH2-350-R4 | C23: 22026214000112 | D23: 350 | G23: 923 | I23: 351 | J23: =I23+$I$40+53 -> 422
B24: MKH2-500-R4 | C24: 22026214000114 | D24: 500 | G24: 1008 | I24: 384 | J24: =I24+$I$40+53 -> 455
B25: MKH2-700-R4 | C25: 22026214000113 | D25: 700 | G25: 1131 | I25: 430 | J25: =I25+$I$40+53 -> 501
B26: MKH2-800-R4 | C26: 22026214000118 | D26: 800 | G26: 1242 | I26: 472 | J26: =I26+$I$40+53 -> 543
B27: / | C27: 12126200000334 | E27: A pair of Supporting bar | G27: 46 | I27: 18
A28: New appearance Ceiling floor | B28: MKH2-150-R3 (A) | C28: 22026214000107 | D28: 150 | E28: 1. two pipe fancoil; 2. air intake from rear; 3. casing with grills on intake and outlet side; 4. drain pan for heat exchanger is standard (drain pan for 3 way valve is option) 5. Flexible installation 6. With built-in controller KJRP-86I/MFK-E | G28: 806 | I28: 307
B29: MKH2-250-R3 (A) | C29: 22026214000109 | D29: 250 | G29: 858 | I29: 327
B30: MKH2-350-R3 (A) | C30: 22026214000110 | D30: 350 | G30: 982 | I30: 374
B31: MKH2-500-R3 (A) | C31: 22026214000116 | D31: 500 | G31: 1086 | I31: 413
B32: MKH2-700-R3 (A) | C32: 22026214000115 | D32: 700 | G32: 1164 | I32: 443
B33: MKH2-800-R3 (A) | C33: 22026214000117 | D33: 800 | G33: 1274 | I33: 485
B34: MKH2-150-R4 (A) | C34: 22026214000108 | D34: 150 | G34: 813 | I34: 309 | J34: =I34+$I$40+53 -> 380
B35: MKH2-250-R4 (A) | C35: 22026214000111 | D35: 250 | G35: 891 | I35: 339 | J35: =I35+$I$40+53 -> 410
B36: MKH2-350-R4 (A) | C36: 22026214000112 | D36: 350 | G36: 1021 | I36: 388 | J36: =I36+$I$40+53 -> 459
B37: MKH2-500-R4 (A) | C37: 22026214000114 | D37: 500 | G37: 1099 | I37: 418 | J37: =I37+$I$40+53 -> 489
B38: MKH2-700-R4 (A) | C38: 22026214000113 | D38: 700 | G38: 1229 | I38: 468 | J38: =I38+$I$40+53 -> 539
B39: MKH2-800-R4 (A) | C39: 22026214000118 | D39: 800 | G39: 1339 | I39: 509 | J39: =I39+$I$40+53 -> 580
B40: 12126200000334 | C40: 12126200000334 | E40: A pair of Supporting bar | G40: 46 | I40: 18
...

Sheet FCUCassette
A1: series | B1: type | C1: MIDEA MODE | E1: Capacity (CFM) | F1: Description of Goods | I1: 0.38
D2: code | G2: Прайс Лист (розница) | I2: Цена со скидкой 62%
A3: AC Cassette Fancoil | B3: MDKD | C3: MKD-300 | D3: 22026212000006 | E3: 300 | F3: 1. Compact Four way cassette type 2. Two pipe fancoil 3. RM12 as standard 4.Build-in drain pump with 500mm head 5. Customized XYE and PQE port to connected to central controller and ModBus gateway as standard | G3: 1027 | I3: 391 | J3: =+I3+$I$7+$I$9 -> 466
C4: MKD-400 | D4: 22026212000012 | E4: 400 | G4: 1112 | I4: 423 | J4: =+I4+$I$7+$I$9 -> 498
C5: MKD-450 | D5: 22026212000012 | E5: 450 | G5: 1112 | I5: 423 | J5: =+I5+$I$7+$I$9 -> 498
C6: MKD-500 | D6: 22026212000027 | E6: 500 | G6: 1209 | I6: 460 | J6: =+I6+$I$7+$I$9 -> 535
C7: T-MBQ4-03B | D7: 12112900000382 | F7: Panel for compact cassette | G7: 143 | I7: 55
C8: 12126200000215 | F8: compact FCU drain pan for 3 way valve for MDKD- | G8: 26 | I8: 10
C9: 12126200000216 | F9: common FCU drain pan for 3 way valve for MDKA- | G9: 52 | I9: 20
B10: MDKA-R | C10: MKA-600R | D10: 22026212000028 | E10: 600 | F10: 1. Common Four way cassette type 2. Two pipe fancoil 3. RM12 as standard 4. Drain pan 5.Build-in drain pump with 750mm head 6.Customized XYE and PQE port to connected to central controller and ModBus gateway as standard | G10: 1177 | I10: 448 | J10: =I10+$I$16 -> 557
C11: MKA-750R | D11: 22026212000004 | E11: 750 | G11: 1216 | I11: 463 | J11: =I11+$I$16 -> 572
C12: MKA-850R | D12: 22026212000053 | E12: 850 | G12: 1463 | I12: 556 | J12: =I12+$I$16 -> 665
C13: MKA-950R | D13: 22026212000023 | E13: 950 | G13: 1508 | I13: 574 | J13: =I13+$I$16 -> 683
C14: MKA-1200R | D14: 22026212000034 | E14: 1200 | G14: 1560 | I14: 593 | J14: =I14+$I$16 -> 702
C15: MKA-1500R | D15: 22026212000034 | E15: 1400 | G15: 1560 | I15: 593 | J15: =I15+$I$16 -> 702
C16: T-MBQ4-02C | D16: 12112900000322 | F16: Panel for common cassette | G16: 286 | I16: 109
B17: MDKC-R-B | C17: MKC-300R-B | E17: 300 | F17: 1. 2nd generation one-way cassette 2.Brand new design with ultrathin frame; 3.New panel; 4.RM12 as standard 5.Build-in drain pump with 750mm head | G17: 1060 | I17: 403
C18: MKC-400R-B | E18: 400 | G18: 1092 | I18: 415
C19: MKC-V600R-B | E19: 600 | G19: 1404 | I19: 534
C20: MBQ1-02D | D20: 12112900000376 | F20: Panel for one-way cassette(300/400) | G20: 221 | I20: 84
C21: MBQ1-01D | D21: 22012900000410 | F21: Panel for one-way cassette(600) | G21: 384 | I21: 146
A22: AC Cassette Fancoil | B22: MDKD-S | C22: MKD-300S | D22: 22026212000059 | E22: 300 | F22: 1. Compact Four way cassette type 2. Four pipe fancoil; 3. RM12 as standard 4.Build-in drain pump with 500mm head 5. Customized XYE and PQE port to connected to central controller and ModBus gateway as standard | G22: 1170 | I22: 445 | J22: =I22+$I$26+$I$27 -> 510
C23: MKD-400S | D23: 22026212000055 | E23: 400 | G23: 1248 | I23: 475 | J23: =I23+$I$26+$I$27 -> 540
C24: MKD-450S | E24: 450 | G24: 1248 | I24: 475 | J24: =I24+$I$26+$I$27 -> 540
C25: MKD-500S | D25: 22026212000008 | E25: 500 | G25: 1339 | I25: 509 | J25: =I25+$I$26+$I$27 -> 574
C26: T-MBQ4-03B | D26: 12112900000382 | F26: Panel for compact cassette | G26: 143 | I26: 55
C27: 12126200000215 | F27: FCU drain pan | G27: 26 | I27: 10
B28: MDKA-F | C28: MKA-600F | D28: 22026212000031 | E28: 600 | F28: 1. Common Four way cassette type 2. Four pipe fancoil; 3. RM12 as standard 4. Drain pan 5.Build-in drain pump with 750mm head 5. Customized XYE and PQE port to connected to central controller and ModBus gateway as standard | G28: 1437 | I28: 547 | J28: =+I28+$I$34 -> 656
C29: MKA-750F | D29: 22026212000041 | E29: 750 | G29: 1632 | I29: 621 | J29: =+I29+$I$34 -> 730
C30: MKA-850F | D30: 22026212000009 | E30: 850 | G30: 1749 | I30: 665 | J30: =+I30+$I$34 -> 774
C31: MKA-950F | D31: 22026212000003 | E31: 950 | G31: 1820 | I31: 692 | J31: =+I31+$I$34 -> 801
C32: MKA-1200F | D32: 22026212000037 | E32: 1200 | G32: 1957 | I32: 744 | J32: =+I32+$I$34 -> 853
C33: MKA-1500F | D33: 22026212000001 | E33: 1400 | G33: 2054 | I33: 781 | J33: =+I33+$I$34 -> 890
C34: T-MBQ4-02C | D34: 12112900000322 | F34: Panel for common cassette | G34: 286 | I34: 109

Sheet DC 2-4-Pipe FCU
A1: series | B1: type | C1: Midea model | D1: Factory code | E1: Capacity (CFM) | F1: Description of Goods | I1: 0.38
G2: Прайс Лист (розница) | I2: Цена со скидкой 62%
A3: Cassette | B3: Compact Four-way cassette | C3: MKD-V300 | D3: 22026212000026 | E3: 300 | F3: 1. Compact Four way cassette type 2. Two pipe fancoil; 3.Build-in drain pump with 500mm head 4.RM 12 standard 5. Customized XYE and PQE port to connected to central controller and ModBus gateway | G3: 995 | I3: 379
C4: MKD-V400 | D4: 22026212000021 | E4: 400 | G4: 1066 | I4: 406
C5: MKD-V500 | D5: 22026212000054 | E5: 500 | G5: 1164 | I5: 443
C6: T-MBQ4-03B | F6: Panel for compact cassette | G6: 143 | I6: 55
C7: 12126200000215 | D7: 12126200000215 | F7: FCU drain pan | G7: 26 | I7: 10
B8: Four-way cassette | C8: MKA-V600R | D8: 22026212000022 | E8: 600 | F8: 1. Common Four way cassette type 2. Two pipe fancoil; 4. Drain pan 5.Build-in drain pump with 750mm head 6.RM 12 standard 7. Customized XYE and PQE port to connected to central controller and ModBus gateway | G8: 1138 | I8: 433
C9: MKA-V750R | D9: 22026212000016 | E9: 750 | G9: 1209 | I9: 460
C10: MKA-V850R | D10: 22026212000047 | E10: 850 | G10: 1333 | I10: 507
C11: MKA-V950R | D11: 22026212000056 | E11: 950 | G11: 1417 | I11: 539
C12: MKA-V1200R | D12: 22026212000032 | E12: 1200 | G12: 1476 | I12: 561
C13: MKA-V1500R | D13: 22026212000025 | E13: 1500 | G13: 1554 | I13: 591
C14: T-MBQ4-02C | D14: 12112900000322 | F14: Panel for common cassette | G14: 286 | I14: 109
B15: One-way cassette | C15: MKC-V300R-B | D15: 22026212000073 | E15: 300 | F15: 1. one-way cassette 2.Brand new design with ultrathin frame; 3. Drain pan 4.Build-in drain pump with 750mm head 5.RM 12 standard 6. Customized XYE and PQE port to connected to central controller and ModBus gateway | G15: 1073 | I15: 408
C16: MKC-V400R-B | D16: 22026212000072 | E16: 400 | G16: 1274 | I16: 485
C17: MKC-V600R-B | D17: 22026212000071 | E17: 600 | G17: 1378 | I17: 524
C18: MBQ1-02D | D18: 12112900000376 | F18: Panel for one-way cassette(300/400) | G18: 221 | I18: 84
C19: MBQ1-01D | D19: 22012900000410 | F19: Panel for one-way cassette(600) | G19: 384 | I19: 146
C20: MKG-V200C | D20: 22026213000016 | E20: 200 | G20: 1066 | I20: 406
B21: A panel | C21: MKG-V250C | D21: 22026213000016 | E21: 250 | F21: 1. new panel 2. Integral 3-way valve 3. Two pipe fancoil 4. RM 12 standard 5. Customized XYE and PQE port to connected to central controller and ModBus gateway | G21: 1131 | I21: 430
C22: MKG-V300C | D22: 22026213000017 | E22: 300 | G22: 1164 | I22: 443
C23: MKG-V400C | D23: 22026213000018 | E23: 400 | G23: 1203 | I23: 458
C24: MKG-V500C | D24: 22026213000019 | E24: 500 | G24: 1294 | I24: 492
C25: MKG-V600C | D25: 22026213000020 | E25: 600 | G25: 1320 | I25: 502
A26: New Ceiling &Floor | B26: 3-row | C26: MKH1-V150-R3 | D26: 借22026214000069 | E26: 150 | F26: 1. DC fan motor 2. 7 fan speed control 3. 200mm thickness 4. Flexible installation; 5. Build-in drain pan for heat exchanger 6. Customized XYE and PQE port to connected to central controller and ModBus gateway | G26: 930 | I26: 354
C27: MKH1-V250-R3 | D27: 借22026214000077 | E27: 250 | G27: 1021 | I27: 388
C28: MKH1-V350-R3 | D28: 借22026214000068 | E28: 300 | G28: 1118 | I28: 425
C29: MKH1-V500-R3 | D29: 借22026214000075 | E29: 500 | G29: 1177 | I29: 448
C30: MKH1-V700-R3 | D30: 借22026214000088 | E30: 700 | G30: 1268 | I30: 482
C31: MKH1-V800-R3 | D31: 借22026214000074 | E31: 800 | G31: 1430 | I31: 544
B32: 4-row | C32: MKH1-V150-R4 | D32: 借22026214000073 | E32: 150 | G32: 956 | I32: 364
C33: MKH1-V250-R4 | D33: 借22026214000078 | E33: 250 | G33: 1060 | I33: 403
C34: MKH1-V350-R4 | D34: 借22026214000076 | E34: 300 | G34: 1170 | I34: 445
C35: MKH1-V500-R4 | D35: 借22026214000070 | E35: 500 | G35: 1248 | I35: 475
C36: MKH1-V700-R4 | D36: 借22026214000087 | E36: 700 | G36: 1333 | I36: 507
C37: MKH1-V800-R4 | D37: 借22026214000067 | E37: 800 | G37: 1521 | I37: 578
B38: 3-row | C38: MKH2-V150-R3 | D38: 22026214000069 | E38: 150 | F38: 1. DC fan motor 2. 7 fan speed control 3. 200mm thickness 4. Flexible installation 5. Build-in drain pan for heat exchanger 6. Customized XYE and PQE port to connected to central controller and ModBus gateway | G38: 930 | I38: 354
C39: MKH2-V250-R3 | D39: 22026214000077 | E39: 250 | G39: 1021 | I39: 388
C40: MKH2-V350-R3 | D40: 22026214000068 | E40: 300 | G40: 1118 | I40: 425
...

Sheet Modular chiller
I1: 0.38
A2: Series | B2: Type | C2: Midea model | D2: Code | E2: Description of Goods | F2: Capacity (kw) | G2: Прайс Лист (розница) | I2: Цена со скидкой 62%
A3: Air cooled modular chiller | B3: Scroll type - R410a T3 Condition | C3: MGBT-F180W/RN1 | E3: • WFS-1001-H • Remote controller KJRM-120D/BMK-E Modbus • XYE (Modbus protocol) • Shell&tube evaporator • EXV • PQE • Scroll type • Sequential phase relay • Default water temperature 7C/12C • Remote On/Off • Remote heating/cooling function | F3: 180 | G3: 65984 | I3: 25074
A4: Air cooled modular chiller | B4: Scroll type - R410a, LAK | C4: MGBL-F200W/RN1 | D4: 22027120000044 | E4: Scroll type; R410a, LAK • WFS-1001-H • Remote controller KJRM-120D/BMK-E Modbus • XYE (Modbus protocol) • Shell&tube evaporator • EXV • PQE • Scroll type • Sequential phase relay • Default water temperature 7C/12C • Remote On/Off • Remote heating/cooling function | F4: 185 | G4: 58916 | I4: 22389
C5: MC-SS35-RN1L-B | D5: 22027120000067 | F5: 35 | G5: 13794 | I5: 5242
C6: MC-SS65/RN1L | D6: 22027120000030 | F6: 65 | G6: 22154 | I6: 8419
C7: MC-SS80/RN1L | D7: 22027120000003 | F7: 80 | G7: 30036 | I7: 11414
A8: Chiller King Series | B8: Chiller King Series (НЕ ПРЕДЛАГАЕМ ЭТУ МОДЕЛЬ) | C8: MC-SS65/RN1 | D8: 21027120000258 | E8: 1. Shell-tube type T1 application 2. R410A 3. Remote controller KJRM-120D/BMK-E Modbus | F8: 65 | G8: 21049 | I8: 7999
C9: MC-SS130/RN1 | D9: 21027120000238 | F9: 130 | G9: 37945 | I9: 14420
A10: Chiller King Plus | B10: Chiller King Plus | C10: MC-SS130-RN1TL | D10: 22027120000458 | E10: Shell-tube type T3 application Remote controller KJRM-120D/BMK-E Modbus | F10: 130 | G10: 39732 | I10: 15099
C11: MC-SS260-RN1TL | D11: 22027120000478 | F11: 260 | G11: 78177 | I11: 29708
B12: Controller | C12: KJR-120A/MBTE | E12: New wired controller for modular chiller, with weekly timer function, compatible with air-cooled modular Lon-work/BACnet Gateway and upper computer software. | G12: 363 | I12: 138
B13: Controller | C13: KJRM-120D/BMK-E | E13: New touch-screen wired controller for modular chiller and Mini Chiller | G13: 501 | I13: 191
B14: Controller | C14: KJR-120H/BMWK03-E | D14: 17317100003115 | G14: 451 | I14: 172
B15: Controller | C15: KJR-120K/BMKO-E | D15: 17317100006835 | G15: 578 | I15: 220
B16: flow switch | C16: WFS-1001-H | E16: Paddle type water flow switch | F16: / | G16: 677 | I16: 258
A17: mini Chiller | B17: Controller | C17: KJR-120F1/BMK-E | D17: 17317100000066 | E17: New touch-screen wired controller for modular chiller and Mini Chiller | F17: / | G17: 501 | I17: 191
B18: mini chiller | C18: MGC-V5WD2N8-B2 | D18: 22025314000599 | E18: 1.220-240V-1N~50Hz 2.DC inverter compressors + DC fan motor 3.Built-in hydraulic module 4.Plate heat exchanger 5. KJRH-120K/BMKO-E as standard | F18: 5 | G18: 5632 | I18: 2141
C19: MGC-V7WD2N8-B2 | D19: 22025314000591 | F19: 7 | G19: 6243 | I19: 2373
C20: MGC-V9WD2N8-B2 | D20: 22025314000592 | F20: 9 | G20: 7926 | I20: 3012
C21: MGC-V12WD2N8-B2 | D21: 借用22025314000593 | F21: 12 | G21: 8778 | I21: 3336
C22: MGC-V14WD2N8-B2 | D22: 借用22025314000594 | F22: 14 | G22: 9312 | I22: 3539
C23: MGC-V16WD2N8-B2 | D23: 借用22025314000595 | F23: 16 | G23: 9818 | I23: 3731
C24: MGC-V18WD2N8-B2 | D24: 22025314000991 | F24: 18 | G24: 10192 | I24: 3873
C25: MGC-V12WD2RN8-B | D25: 22025314000596 | E25: 1.380-400V-3N~50Hz 2.DC inverter compressors + DC fan motor 3.Built-in hydraulic module 4.Plate heat exchanger 5. KJRH-120K/BMKO-E as standard | F25: 12 | G25: 10192 | I25: 3873
C26: MGC-V14WD2RN8-B | D26: 22025314000597 | F26: 14 | G26: 10269 | I26: 3903
C27: MGC-V16WD2RN8-B | D27: 22025314000598 | F27: 16 | G27: 11248 | I27: 4275
A28: Aqua thermal | C28: MC-SU75-RN8L-B | D28: 22027120000398 | E28: R32 R32 KJRM-120H2/BMWK Modbus | F28: 75 | G28: 21681 | I28: 8239
C29: MC-SU90-RN8L-B | D29: 22027120000378 | E29: Modbus RTU R32 KJRM-120H2/BMWK Modbus | F29: 90 | G29: 30938 | I29: 11757
B30: эта модель идет на замену стандартной MC-SS130/RN1 | C30: MC-SU140-RN8L-B | D30: 22027120000418 | E30: Without hydraulic module can be customized R32 KJRM-120H2/BMWK Modbus | F30: 140 | G30: 40926 | I30: 15552
C31: MC-SU180-RN8L-B | D31: 22027120000438 | E31: R32 KJRM-120H2/BMWK Modbus | F31: 180 | G31: 88022 | I31: 33449
A32: Aqua thermal（M) | C32: MC-SU75M-RN8L-B | D32: 22027120000398 | E32: R32With hydraulic module | F32: 75 | G32: 26560 | I32: 10093
C33: MC-SU90M-RN8L-B | D33: 22027120000378 | E33: Modbus RTU, With hydraulic module | F33: 90 | G33: 37719 | I33: 14334
C34: MC-SU140M-RN8L-B | D34: 22027120000418 | E34: With hydraulic module | F34: 140 | G34: 50424 | I34: 19162
C35: MC-SU180M-RN8L-B | D35: 22027120000438 | E35: With hydraulic module | F35: 180 | G35: 102498 | I35: 38950
C36: GW-BAC(MC) | D36: 17211200002201 | G36: 7832 | I36: 2977
A37: Aqua thermal Super /T1/LA DC Inverter Plate heat exchanger T1 application LA | B37: R32 | C37: MH-SU50-RN8L | D37: 借22025314000671 方案号L2023071466341 | E37: DC Inverter commercial type heat pump Plate heat exchanger | F37: 50 | G37: 31433 | I37: 11945
B38: R32 | C38: MH-SU65-RN8L | D38: 22025314000671 | F38: 65 | G38: 32709 | I38: 12430
B39: R32 | C39: MH-SU75-RN8L | D39: 借22025314000671 方案号L2022122744465 | F39: 75 | G39: 33908 | I39: 12886
B40: R32 | C40: MH-SU110-RN8L | D40: 22025314000691 | F40: 110 | G40: 53686 | I40: 20401
...

Sheet Heat Pump
I1: 0.38
A2: Series | B2: Type | C2: Midea Model | D2: Factory Code | E2: Description of Goods | F2: Capacity (kw) | G2: Прайс Лист (розница) | I2: Цена со скидкой 62%
A3: M thermal Arctic | B3: Mono | C3: MHC-V4W/D2N8-B | D3: 22025314000658 | E3: R32 220-240V~50Hz | F3: 4 | G3: 7861 | I3: 2988
C4: MHC-V6W/D2N8-B | D4: 22025314000654 | F4: 6 | G4: 8094 | I4: 3076
C5: MHC-V8W/D2N8-B | D5: 22025314000657 | F5: 8 | G5: 8944 | I5: 3399
C6: MHC-V10W/D2N8-B | D6: 22025314000656 | F6: 10 | G6: 9058 | I6: 3443
C7: MHC-V12W/D2N8-B | D7: 22025314000651 | F7: 12 | G7: 11748 | I7: 4465
C8: MHC-V14W/D2N8-B | D8: 22025314000652 | F8: 14 | G8: 11902 | I8: 4523
C9: MHC-V16W/D2N8-B | D9: 22025314000653 | F9: 16 | G9: 12096 | I9: 4597
C10: MHC-V12W/D2RN8-B | D10: 22025314000659 | E10: R32 380-415V~3N-50Hz | F10: 12 | G10: 12193 | I10: 4634
C11: MHC-V14W/D2RN8-B | D11: 22025314000655 | F11: 14 | G11: 12466 | I11: 4738
C12: MHC-V16W/D2RN8-B | D12: 22025314000660 | F12: 16 | G12: 12854 | I12: 4885
C13: MHC-V18W/D2RN8 | D13: 22025314000491 | F13: 18 | G13: 16263 | I13: 6180
C14: MHC-V22W/D2RN8 | D14: 22025314000493 | F14: 22 | G14: 16701 | I14: 6347
C15: MHC-V26W/D2RN8 | D15: 22025314000471 | F15: 26 | G15: 16986 | I15: 6455
C16: MHC-V30W/D2RN8 | D16: 22025314000492 | F16: 30 | G16: 17271 | I16: 6563
B17: Split ODU | C17: MHA-V4W/D2N8-B | D17: 22025314000618 | E17: R32 220-240V~50Hz | F17: 4 | G17: 3723 | I17: 1415
C18: MHA-V6W/D2N8-B | D18: 22025314000613 | F18: 6 | G18: 3728 | I18: 1417
C19: MHA-V8W/D2N8-B | D19: 22025314000616 | F19: 8 | G19: 4247 | I19: 1614
C20: MHA-V10W/D2N8-B | D20: 22025314000614 | F20: 10 | G20: 4515 | I20: 1716
C21: MHA-V12W/D2N8-B | D21: 22025314000634 | F21: 12 | G21: 6584 | I21: 2502
C22: MHA-V14W/D2N8-B | D22: 22025314000615 | F22: 14 | G22: 6886 | I22: 2617
C23: MHA-V16W/D2N8-B | D23: 借22025314000615 | F23: 16 | G23: 7046 | I23: 2678
C24: MHA-V12W/D2RN8-B | D24: 22025314000611 | E24: R32 380-415V~3N-50Hz | F24: 12 | G24: 7314 | I24: 2780
C25: MHA-V14W/D2RN8-B | D25: 22025314000637 | F25: 14 | G25: 7433 | I25: 2825
C26: MHA-V16W/D2RN8-B | D26: 借22025314000637 | F26: 16 | G26: 7621 | I26: 2896
B27: Split hydraulic module | C27: HB-A60/CGN8-B | D27: 22025314000433 | E27: R32，380-415V~3N-50Hz additional electrical heater: 3kw: 88 USD, 9kw: 120 USD | F27: 6 | G27: 4486 | I27: 1705
C28: HB-A100/CGN8-B | D28: 22025314000432 | F28: 10 | G28: 4549 | I28: 1729
C29: HB-A160/CGN8-B | D29: 22025314000431 | F29: 14 | G29: 4680 | I29: 1779
B30: Split IDU with tank | C30: HBT-A100/190CD30GN8-B | D30: 22025331000061 | E30: R32 3kw heater: 220-240V~50Hz 9kw heater: 380-415V~3N-50Hz | F30: 190L | G30: 10181 | I30: 3869
C31: HBT-A160/240CD30GN8-B | D31: 22025331000062 | F31: 240L | G31: 11913 | I31: 4527
C32: HBT-A160/240CDS90GN8-B | D32: 22025331000062 | F32: 240L | G32: 12489 | I32: 4746
C33: HBT-A100/240CD30GN8-B | D33: 22025331000062 | F33: 240L | G33: 12107 | I33: 4601
C34: HBT-A100/240CDS90GN8-B | D34: 22025331000062 | F34: 240L | G34: 12683 | I34: 4820
A35: Commercial type Heat pump water heater | B35: Commercial type Heat pump water heater | C35: RSJ-120/ZN1-540V1 | D35: 22025310000369 | E35: 220-240V-1N~50Hz | F35: 12 | G35: 8237 | I35: 3131
C36: RSJ-200/SZN1-540V1 | D36: 22025313000087 | E36: 380-415V 3N~50Hz | F36: 20 | G36: 10175 | I36: 3867
C37: RSJ-420/SZN1-H | D37: 22025313000006 | F37: 42 | G37: 17574 | I37: 6679
C38: RSJ-800/SZN1-H | D38: 22025310000017 | F38: 80 | G38: 35808 | I38: 13608
A39: pool heat pump | C39: MSC-70D2N8-A | D39: 22025320000026 | E39: 220-240V~50Hz | F39: 7 | G39: 3631 | I39: 1380
C40: MSC-90D2N8-A | D40: 22025320000024 | E40: 220-240V~50Hz | F40: 9 | G40: 3882 | I40: 1476
...

Sheet Rooftop
I1: 0.38
A2: Series | B2: Type | C2: Midea model | D2: BOM CODE | E2: Description of Goods | F2: Capacity (kw) | G2: Прайс Лист (розница) | I2: Цена со скидкой 62%
A3: Clima Creator | B3: Heat pump | C3: MRC-075HWN1-R(C ) | D3: 22027710000302 | E3: 1. R410A 2. Cooling & heating 3. 380V/3ph/50hz; 4. side discharge | F3: 27 | G3: 10158 | I3: 3861
C4: MRC-100HWN1-R(C) | D4: 22027710000048 | F4: 35 | G4: 13527 | I4: 5141
C5: MRC-125HWN1-R(C) | D5: 22027710000164 | F5: 43 | G5: 18833 | I5: 7157
C6: MRC-150HWN1-R(C) | D6: 22027710000157 | F6: 53 | G6: 21364 | I6: 8119
C7: MRC-175HWN1-R(C) | D7: 22027710000111 | F7: 62 | G7: 25713 | I7: 9771
C8: MRC-200HWN1-R(C) | D8: 22027710000158 | F8: 70 | G8: 26802 | I8: 10185
C9: MRC-250HWN1-R(C) | D9: 22027710000289 | F9: 88 | G9: 32929 | I9: 12514
C10: MRC-300HWN1-R(C) | D10: 22027710000321 | F10: 105 | G10: 42927 | I10: 16313
B11: Cooling only | C11: MRCT-062CWN1-R(C) | D11: 22027710000020 | E11: 1. R410A 2. Cooling only type; 3. 380V/3ph/50hz; 4. Tropical type 5. side discharge(Up&down) | F11: 22 | G11: 9605 | I11: 3650
C12: MRCT-075CWN1-R(C) | D12: 22027710000021 | F12: 27 | G12: 10887 | I12: 4138
C13: MRCT-085CWN1-R(D) | D13: 22027710000351 | F13: 30 | G13: 12501 | I13: 4751
C14: MRCT-100CWN1-R(D) | D14: 22027710000350 | F14: 35 | G14: 12865 | I14: 4889
C15: MRCT-125CWN1-R(C) | D15: 22027710000029 | F15: 44 | G15: 17733 | I15: 6739
C16: MRCT-150CWN1-R(C) | D16: 22027710000222 | F16: 53 | G16: 22191 | I16: 8433
C17: MRCT-175CWN1-R(C) | D17: 22027710000094 | F17: 62 | G17: 24756 | I17: 9408
C18: MRCT-200CWN1-R(C) | D18: 22027710000224 | F18: 70 | G18: 27879 | I18: 10595
C19: MRCT-250CWN1-R(C) | D19: 22027710000364 | F19: 88 | G19: 32137 | I19: 12213
C20: MRCT-300CWN1-R(C) | D20: 22027710000363 | F20: 105 | G20: 42517 | I20: 16157

Sheet OLD V8
A1: Series | B1: Power Supply | C1: MDV model | D1: MDV model (JAC) | F1: Factory code | G1: Description | H1: Capacity Kw | I1: Unit price (CNY) | J1: Questions
A2: V8 Master | B2: 380-415V ~ 3N ~ 50/60Hz | C2: MDVO-V8252V2R1A(MA) | D2: MDV-V8252V2R1A(MA) | E2: MV8-252WV2GN1(MA) | F2: 22027020002389 | G2: 1.Chassis electrical heater 2.Automatic refrigerant charging 3.Bluetooth module (with black box) 4.single outdoor unit ratio 200% 5. V8 system can connect 30% indoor units 6. Auto dust-clean function 7. Humidity control (in IDU) | H2: 25.2 | I2: 20665
C3: MDVO-V8280V2R1A(MA) | D3: MDV-V8280V2R1A(MA) | E3: MV8-280WV2GN1(MA) | F3: 22027020002392 | H3: 28 | I3: 21296
C4: MDVO-V8335V2R1A(MA) | D4: MDV-V8335V2R1A(MA) | E4: MV8-335WV2GN1(MA) | F4: 22027020002305 | H4: 33.5 | I4: 23659
C5: MDVO-V8400V2R1A(MA) | D5: MDV-V8400V2R1A(MA) | E5: MV8-400WV2GN1(MA) | F5: 22027020002397 | H5: 40 | I5: 27665
C6: MDVO-V8450V2R1A(MA) | D6: MDV-V8450V2R1A(MA) | E6: MV8-450WV2GN1(MA) | F6: 22027020002391 | H6: 45 | I6: 28877
C7: MDVO-V8500V2R1A(MA) | D7: MDV-V8500V2R1A(MA) | E7: MV8-500WV2GN1(MA) | F7: 22027020002265 | H7: 50 | I7: 34597
C8: MDVO-V8560V2R1A(MA) | D8: MDV-V8560V2R1A(MA) | E8: MV8-560WV2GN1(MA) | F8: 22027020002347 | H8: 56 | I8: 35493
C9: MDVO-V8615V2R1A(MA) | D9: MDV-V8615V2R1A(MA) | E9: MV8-615WV2GN1(MA) | F9: 22027020002346 | H9: 61.5 | I9: 37889
C10: MDVO-V8670V2R1A(MA) | D10: MDV-V8670V2R1A(MA) | E10: MV8-670WV2GN1(MA) | F10: 22027020002345 | H10: 67 | I10: 42614
C11: MDVO-V8730V2R1A(MA) | D11: MDV-V8730V2R1A(MA) | E11: MV8-730WV2GN1(MA) | F11: 22027020002365 | H11: 73 | I11: 44593
C12: MDVO-V8785V2R1A(MA) | D12: MDV-V8785V2R1A(MA) | E12: MV8-785WV2GN1(MA) | F12: 22027020002286 | H12: 78.5 | I12: 46667
C13: MDVO-V8850V2R1A(MA) | D13: MDV-V8850V2R1A(MA) | E13: MV8-850WV2GN1(MA) | F13: 22027020002285 | H13: 85 | I13: 50334
C14: MDVO-V8900V2R1A(MA) | D14: MDV-V8900V2R1A(MA) | E14: MV8-900WV2GN1(MA) | F14: 22027020002393 | H14: 90 | I14: 50732
... C18: MDVO-V81120V2R1A(MA) | D18: MDV-V81120V2R1A(MA) | E18: MV8-1120WV2GN1(MA) | F18: 22027020002325 | H18: 112 | I18: 58653
A19: V8i Master | B19: 380-415V ~ 3N ~ 50/60Hz | C19: MDVO-V8i252V2R1A(MA) | D19: MDV-V8i252V2R1A(MA) | E19: MV8i-252WV2GN1(MA) | F19: 22027020002647 | G19: 1.Chassis electrical heater 2.Automatic refrigerant charging 3.Bluetooth module (with black box) 4.single outdoor unit ratio 200% 5. V8 system can connect 30% indoor units 6. Auto dust-clean function 7. Humidity control (in IDU) | H19: 25.2 | I19: 17009
C20: MDVO-V8i280V2R1A(MA) | D20: MDV-V8i280V2R1A(MA) | E20: MV8i-280WV2GN1(MA) | F20: 22027020002633 | H20: 28 | I20: 17326
C21: MDVO-V8i335V2R1A(MA) | D21: MDV-V8i335V2R1A(MA) | E21: MV8i-335WV2GN1(MA) | F21: 22027020002646 | H21: 33.5 | I21: 19897
C22: MDVO-V8i400V2R1A(MA) | D22: MDV-V8i400V2R1A(MA) | E22: MV8i-400WV2GN1(MA) | F22: 22027020002637 | H22: 40 | I22: 23269
C23: MDVO-V8i450V2R1A(MA) | D23: MDV-V8i450V2R1A(MA) | E23: MV8i-450WV2GN1(MA) | F23: 22027020002623 | H23: 45 | I23: 23639
C24: MDVO-V8i500V2R1A(MA) | D24: MDV-V8i500V2R1A(MA) | E24: MV8i-500WV2GN1(MA) | F24: 22027020002645 | H24: 50 | I24: 26331
C25: MDVO-V8i560V2R1A(MA) | D25: MDV-V8i560V2R1A(MA) | E25: MV8i-560WV2GN1(MA) | F25: 22027020002629 | H25: 56 | I25: 27900
C26: MDVO-V8i615V2R1A(MA) | D26: MDV-V8i615V2R1A(MA) | E26: MV8i-615WV2GN1(MA) | F26: 22027020002630 | H26: 61.5 | I26: 30410
C27: MDVO-V8i670V2R1A(MA) | D27: MDV-V8i670V2R1A(MA) | E27: MV8i-670WV2GN1(MA) | F27: 22027020002627 | H27: 67 | I27: 33305
C28: MDVO-V8i730V2R1A(MA) | D28: MDV-V8i730V2R1A(MA) | E28: MV8i-730WV2GN1(MA) | F28: 22027020002608 | H28: 73 | I28: 41820
C29: MDVO-V8i785V2R1A(MA) | D29: MDV-V8i785V2R1A(MA) | E29: MV8i-785WV2GN1(MA) | F29: 22027020002609 | H29: 78.5 | I29: 42156
C30: MDVO-V8i850V2R1A(MA) | D30: MDV-V8i850V2R1A(MA) | E30: MV8i-850WV2GN1(MA) | F30: 22027020002619 | H30: 85 | I30: 43529
C31: MDVO-V8i900V2R1A(MA) | D31: MDV-V8i900V2R1A(MA) | E31: MV8i-900WV2GN1(MA) | F31: 22027020002618 | H31: 90 | I31: 46303
... C35: MDVO-V8i1120V2R1A(MA) | D35: MDV-V8i1120V2R1A(MA) | E35: MV8i-1120WV2GN1(MA) | F35: 22027020002625 | H35: 112 | I35: 52765
C36: MDVO-V8i1170V2R1A(MA) | D36: MDV-V8i1170V2R1A(MA) | F36: 22027020002614 | H36: 117 | I36: 53421
A37: V8S (Projects, CIS sales only) | B37: 380-415V ~ 3N ~ 50/60Hz | C37: MDVO-V8S252V2R1A | D37: MDV-V8S252V2R1A | F37: 22027020002412 | G37: 1.Chassis electrical heater - не включено 2.Automatic refrigerant charging 3.Bluetooth module (with black box) 4.single outdoor unit ratio 200% 5. V8 system can connect 30% indoor units 6. Auto dust-clean function 7. Humidity control (in IDU) | H37: 25.2 | I37: 18888
C38: MDVO-V8S280V2R1A | D38: MDV-V8S280V2R1A | F38: 22027020002413 | H38: 28 | I38: 20092
C39: MDVO-V8S335V2R1A | D39: MDV-V8S335V2R1A | F39: 22027020002410 | H39: 33.5 | I39: 22239
C40: MDVO-V8S400V2R1A | D40: MDV-V8S400V2R1A | F40: 22027020002407 | H40: 40 | I40: 24313
C41: MDVO-V8S450V2R1A | D41: MDV-V8S450V2R1A | F41: 22027020002408 | H41: 45 | I41: 26280
C42: MDVO-V8S500V2R1A | D42: MDV-V8S500V2R1A | F42: 22027020002411 | H42: 50 | I42: 28567
C43: MDVO-V8S560V2R1A | D43: MDV-V8S560V2R1A | F43: 22027020002406 | H43: 56 | I43: 32075
C44: MDVO-V8S615V2R1A | D44: MDV-V8S615V2R1A | F44: 22027020002405 | H44: 61.5 | I44: 34079
C45: MDVO-V8S670V2R1A | D45: MDV-V8S670V2R1A | F45: 22027020002409 | H45: 67 | I45: 37220
A46: Easyfit | B46: 380-415V ~ 3N ~ 50/60Hz | C46: MDVO-Vi252V2R1A | D46: MDV-Vi252V2R1A | E46: MVi-252WV2GN1(B) | F46: 22027020002998 | G46: 1.Auto dust-clean function 2.Automatic refrigerant charging 3.Bluetooth module (with black box) 4.Wide combination ratio 30%-200% 5. Humidity control (in IDU) | H46: 25.2 | I46: 16046
...
